<?xml version="1.0" encoding="utf-8"?>
<!-- This URDF was automatically created by SolidWorks to URDF Exporter! Originally created by Stephen Brawner (brawner@gmail.com) 
     Commit Version: 1.5.1-0-g916b5db  Build Version: 1.5.7152.31018
     For more information, please see http://wiki.ros.org/sw_urdf_exporter -->
<robot
  name="model20">
  <link
    name="base_link">
    <inertial>
      <origin
        xyz="-0.092833848330563 0.0774406058847294 0.0426424242481935"
        rpy="0 0 0" />
      <mass
        value="3.21829386296279" />
      <inertia
        ixx="0.00580151653868739"
        ixy="1.9364341074558E-06"
        ixz="6.92633511445308E-07"
        iyy="0.00721990996747051"
        iyz="3.86677335720294E-07"
        izz="0.0125117312153311" />
    </inertial>
    <visual>
      <origin
        xyz="0 0 0"
        rpy="0 0 0" />
      <geometry>
        <mesh
          filename="package://model20/meshes/base_link.STL" />
      </geometry>
      <material
        name="">
        <color
          rgba="0.752941176470588 0.752941176470588 0.752941176470588 1" />
      </material>
    </visual>
    <collision>
      <origin
        xyz="0 0 0"
        rpy="0 0 0" />
      <geometry>
        <mesh
          filename="package://model20/meshes/base_link.STL" />
      </geometry>
    </collision>
  </link>
  <link
    name="left_front_wheel_suspension">
    <inertial>
      <origin
        xyz="-0.00786753377996494 -0.0155948984609842 0.0232556468762561"
        rpy="0 0 0" />
      <mass
        value="0.0651133753252895" />
      <inertia
        ixx="1.48802654908116E-05"
        ixy="1.64845451975805E-08"
        ixz="-1.56420031463122E-07"
        iyy="1.75245555055195E-05"
        iyz="-2.96403540336111E-09"
        izz="8.01010024686586E-06" />
    </inertial>
    <visual>
      <origin
        xyz="0 0 0"
        rpy="0 0 0" />
      <geometry>
        <mesh
          filename="package://model20/meshes/left_front_wheel_suspension.STL" />
      </geometry>
      <material
        name="">
        <color
          rgba="0.752941176470588 0.752941176470588 0.752941176470588 1" />
      </material>
    </visual>
    <collision>
      <origin
        xyz="0 0 0"
        rpy="0 0 0" />
      <geometry>
        <mesh
          filename="package://model20/meshes/left_front_wheel_suspension.STL" />
      </geometry>
    </collision>
  </link>
  <joint
    name="left_front_wheel_suspension_joint"
    type="prismatic">
    <origin
      xyz="-0.019998715602551 0.155491237481961 -0.0309978167969167"
      rpy="1.5707963267949 0 -1.5707963267949" />
    <parent
      link="base_link" />
    <child
      link="left_front_wheel_suspension" />
    <axis
      xyz="0 1 0" />
    <limit
      lower="0"
      upper="0"
      effort="0"
      velocity="0" />
  </joint>
  <link
    name="left_front_wheel">
    <inertial>
      <origin
        xyz="0.0158399891826273 -4.59981459866032E-09 7.99690621500204E-08"
        rpy="0 0 0" />
      <mass
        value="0.22822169800504" />
      <inertia
        ixx="0.000789211576324214"
        ixy="-1.09995507949593E-10"
        ixz="1.91230261060067E-09"
        iyy="0.000410429434291453"
        iyz="-5.55677330321344E-16"
        izz="0.000410429434301075" />
    </inertial>
    <visual>
      <origin
        xyz="0 0 0"
        rpy="0 0 0" />
      <geometry>
        <mesh
          filename="package://model20/meshes/left_front_wheel.STL" />
      </geometry>
      <material
        name="">
        <color
          rgba="1 1 1 1" />
      </material>
    </visual>
    <collision>
      <origin
        xyz="0 0 0"
        rpy="0 0 0" />
      <geometry>
        <mesh
          filename="package://model20/meshes/left_front_wheel.STL" />
      </geometry>
    </collision>
  </link>
  <joint
    name="left_front_wheel_joint"
    type="continuous">
    <origin
      xyz="-0.0197601403859578 -0.0217865728752538 0.00999990007507129"
      rpy="3.08413603591628 0 3.14159265358979" />
    <parent
      link="left_front_wheel_suspension" />
    <child
      link="left_front_wheel" />
    <axis
      xyz="0.999999999987214 0 0" />
    <limit
      effort="3.1"
      velocity="7" />
  </joint>
  <link
    name="right_front_wheel_suspension">
    <inertial>
      <origin
        xyz="-0.00415434378457435 -0.0156302499401892 0.0232556866612721"
        rpy="0 0 0" />
      <mass
        value="0.0651133753251555" />
      <inertia
        ixx="1.48802639086072E-05"
        ixy="1.648453020563E-08"
        ixz="1.56454773175217E-07"
        iyy="1.75245555054544E-05"
        iyz="2.96411876510215E-09"
        izz="8.01010182899685E-06" />
    </inertial>
    <visual>
      <origin
        xyz="0 0 0"
        rpy="0 0 0" />
      <geometry>
        <mesh
          filename="package://model20/meshes/right_front_wheel_suspension.STL" />
      </geometry>
      <material
        name="">
        <color
          rgba="0.752941176470588 0.752941176470588 0.752941176470588 1" />
      </material>
    </visual>
    <collision>
      <origin
        xyz="0 0 0"
        rpy="0 0 0" />
      <geometry>
        <mesh
          filename="package://model20/meshes/right_front_wheel_suspension.STL" />
      </geometry>
    </collision>
  </link>
  <joint
    name="right_front_wheel_suspension_joint"
    type="prismatic">
    <origin
      xyz="-0.019998685205965 -0.0145086967784139 -0.0309978167969166"
      rpy="1.5707963267949 0 -1.5707963267949" />
    <parent
      link="base_link" />
    <child
      link="right_front_wheel_suspension" />
    <axis
      xyz="0 1 0" />
    <limit
      lower="0"
      upper="0"
      effort="0"
      velocity="0" />
  </joint>
  <link
    name="right_front_wheel">
    <inertial>
      <origin
        xyz="0.015839199018542 1.11022302462516E-16 0"
        rpy="0 0 0" />
      <mass
        value="0.22822169800504" />
      <inertia
        ixx="0.000789211576333899"
        ixy="-3.39114589672057E-20"
        ixz="5.36354242059181E-21"
        iyy="0.000410429434291421"
        iyz="-3.3881317890172E-19"
        izz="0.000410429434291419" />
    </inertial>
    <visual>
      <origin
        xyz="0 0 0"
        rpy="0 0 0" />
      <geometry>
        <mesh
          filename="package://model20/meshes/right_front_wheel.STL" />
      </geometry>
      <material
        name="">
        <color
          rgba="1 1 1 1" />
      </material>
    </visual>
    <collision>
      <origin
        xyz="0 0 0"
        rpy="0 0 0" />
      <geometry>
        <mesh
          filename="package://model20/meshes/right_front_wheel.STL" />
      </geometry>
    </collision>
  </link>
  <joint
    name="right_front_wheel_joint"
    type="continuous">
    <origin
      xyz="0.00773912001850283 -0.0217849999999998 0.0100000000000001"
      rpy="0.162600051915931 0 0" />
    <parent
      link="right_front_wheel_suspension" />
    <child
      link="right_front_wheel" />
    <axis
      xyz="1 0 0" />
    <limit
      effort="3.1"
      velocity="7" />
  </joint>
  <link
    name="camera">
    <inertial>
      <origin
        xyz="0.00574434029795978 -0.000740342879783772 -0.0662231976935658"
        rpy="0 0 0" />
      <mass
        value="0.0436119957238953" />
      <inertia
        ixx="2.34834564028883E-05"
        ixy="-1.21278036982022E-09"
        ixz="-3.47379224009179E-07"
        iyy="4.2947905005604E-06"
        iyz="-5.91274656944023E-10"
        izz="2.2193065138918E-05" />
    </inertial>
    <visual>
      <origin
        xyz="0 0 0"
        rpy="0 0 0" />
      <geometry>
        <mesh
          filename="package://model20/meshes/camera.STL" />
      </geometry>
      <material
        name="">
        <color
          rgba="0.792156862745098 0.819607843137255 0.933333333333333 1" />
      </material>
    </visual>
    <collision>
      <origin
        xyz="0 0 0"
        rpy="0 0 0" />
      <geometry>
        <mesh
          filename="package://model20/meshes/camera.STL" />
      </geometry>
    </collision>
  </link>
  <joint
    name="camera"
    type="fixed">
    <origin
      xyz="-0.0134999999999999 0.0764920649895213 0.154987708684933"
      rpy="0 0 0" />
    <parent
      link="base_link" />
    <child
      link="camera" />
    <axis
      xyz="0 0 0" />
  </joint>
  <link
    name="camera2">
    <inertial>
      <origin
        xyz="-0.0221485658915229 0.000718215963980057 0.0651474645619419"
        rpy="0 0 0" />
      <mass
        value="0.0436119950287125" />
      <inertia
        ixx="2.34616976848218E-05"
        ixy="-7.5418513253527E-10"
        ixz="3.85065873476792E-07"
        iyy="4.29479133591139E-06"
        iyz="-1.11912173840941E-09"
        izz="2.22148222430625E-05" />
    </inertial>
    <visual>
      <origin
        xyz="0 0 0"
        rpy="0 0 0" />
      <geometry>
        <mesh
          filename="package://model20/meshes/camera2.STL" />
      </geometry>
      <material
        name="">
        <color
          rgba="0.792156862745098 0.819607843137255 0.933333333333333 1" />
      </material>
    </visual>
    <collision>
      <origin
        xyz="0 0 0"
        rpy="0 0 0" />
      <geometry>
        <mesh
          filename="package://model20/meshes/camera2.STL" />
      </geometry>
    </collision>
  </link>
  <joint
    name="camera2"
    type="fixed">
    <origin
      xyz="-0.00852200766865335 0.0757627858576307 0.0876258392043087"
      rpy="0 0.261799387799143 0" />
    <parent
      link="base_link" />
    <child
      link="camera2" />
    <axis
      xyz="0 0 0" />
  </joint>
  <link
    name="lidar">
    <inertial>
      <origin
        xyz="-0.00868778989367724 -0.00242014065569161 -0.0287648859064543"
        rpy="0 0 0" />
      <mass
        value="0.0730845706123877" />
      <inertia
        ixx="1.9580875609635E-05"
        ixy="-1.03933750344927E-07"
        ixz="4.28391241039135E-07"
        iyy="2.41250086763081E-05"
        iyz="-9.42709906914289E-09"
        izz="4.1418452244397E-05" />
    </inertial>
    <visual>
      <origin
        xyz="0 0 0"
        rpy="0 0 0" />
      <geometry>
        <mesh
          filename="package://model20/meshes/lidar.STL" />
      </geometry>
      <material
        name="">
        <color
          rgba="0.792156862745098 0.819607843137255 0.933333333333333 1" />
      </material>
    </visual>
    <collision>
      <origin
        xyz="0 0 0"
        rpy="0 0 0" />
      <geometry>
        <mesh
          filename="package://model20/meshes/lidar.STL" />
      </geometry>
    </collision>
  </link>
  <joint
    name="lidar_joint"
    type="fixed">
    <origin
      xyz="-0.0642592027859291 0.0687050562666345 0.223497816796912"
      rpy="0 0 0" />
    <parent
      link="base_link" />
    <child
      link="lidar" />
    <axis
      xyz="0 0 0" />
  </joint>
  <link
    name="imu">
    <inertial>
      <origin
        xyz="0 1.38777878078145E-17 0.00250000000000002"
        rpy="0 0 0" />
      <mass
        value="0.000510000000000001" />
      <inertia
        ixx="5.31250000000002E-09"
        ixy="-7.37257477290141E-26"
        ixz="-1.57807179640438E-40"
        iyy="5.31250000000002E-09"
        iyz="-5.52943107967612E-26"
        izz="8.50000000000004E-09" />
    </inertial>
    <visual>
      <origin
        xyz="0 0 0"
        rpy="0 0 0" />
      <geometry>
        <mesh
          filename="package://model20/meshes/imu.STL" />
      </geometry>
      <material
        name="">
        <color
          rgba="1 1 1 1" />
      </material>
    </visual>
    <collision>
      <origin
        xyz="0 0 0"
        rpy="0 0 0" />
      <geometry>
        <mesh
          filename="package://model20/meshes/imu.STL" />
      </geometry>
    </collision>
  </link>
  <joint
    name="imu"
    type="fixed">
    <origin
      xyz="-0.0950000000000001 0.117752824450965 0.169997816796917"
      rpy="0 0 0" />
    <parent
      link="base_link" />
    <child
      link="imu" />
    <axis
      xyz="0 0 0" />
  </joint>
  <link
    name="left_rear_wheel_suspension">
    <inertial>
      <origin
        xyz="0 -0.005 1.11022302462516E-16"
        rpy="0 0 0" />
      <mass
        value="0.00774637194071073" />
      <inertia
        ixx="3.9707044697232E-07"
        ixy="-2.59626609761759E-23"
        ixz="1.7265241970474E-23"
        iyy="6.65034694932794E-07"
        iyz="-4.68375338513749E-24"
        izz="3.97070446972319E-07" />
    </inertial>
    <visual>
      <origin
        xyz="0 0 0"
        rpy="0 0 0" />
      <geometry>
        <mesh
          filename="package://model20/meshes/left_rear_wheel_suspension.STL" />
      </geometry>
      <material
        name="">
        <color
          rgba="0.898039215686275 0.917647058823529 0.929411764705882 1" />
      </material>
    </visual>
    <collision>
      <origin
        xyz="0 0 0"
        rpy="0 0 0" />
      <geometry>
        <mesh
          filename="package://model20/meshes/left_rear_wheel_suspension.STL" />
      </geometry>
    </collision>
  </link>
  <joint
    name="left_rear_wheel_suspension_joint"
    type="prismatic">
    <origin
      xyz="-0.293 0.1615 -0.030998"
      rpy="1.5708 0 -1.5708" />
    <parent
      link="base_link" />
    <child
      link="left_rear_wheel_suspension" />
    <axis
      xyz="0 1 0" />
    <limit
      lower="0"
      upper="0"
      effort="0"
      velocity="0" />
  </joint>
  <link
    name="left_rear_wheel">
    <inertial>
      <origin
        xyz="0 -0.0404395006329032 0"
        rpy="0 0 0" />
      <mass
        value="0.342512288692214" />
      <inertia
        ixx="0.000165711359519628"
        ixy="1.00962097199719E-21"
        ixz="6.2469123454979E-21"
        iyy="0.00011406556894596"
        iyz="3.79469691957732E-21"
        izz="0.000165711359519627" />
    </inertial>
    <visual>
      <origin
        xyz="0 0 0"
        rpy="0 0 0" />
      <geometry>
        <mesh
          filename="package://model20/meshes/left_rear_wheel.STL" />
      </geometry>
      <material
        name="">
        <color
          rgba="0.898039215686275 0.917647058823529 0.929411764705882 1" />
      </material>
    </visual>
    <collision>
      <origin
        xyz="0 0 0"
        rpy="0 0 0" />
      <geometry>
        <mesh
          filename="package://model20/meshes/left_rear_wheel.STL" />
      </geometry>
    </collision>
  </link>
  <joint
    name="left_rear_wheel_joint"
    type="fixed">
    <origin
      xyz="0 -0.019515762701871 0"
      rpy="0 0 0" />
    <parent
      link="left_rear_wheel_suspension" />
    <child
      link="left_rear_wheel" />
    <axis
      xyz="0 0 0" />
  </joint>
  <link
    name="right_rear_wheel_suspension">
    <inertial>
      <origin
        xyz="0 -0.005 -1.11022302462516E-16"
        rpy="0 0 0" />
      <mass
        value="0.00774637194071073" />
      <inertia
        ixx="3.9707044697232E-07"
        ixy="-2.59626609761758E-23"
        ixz="5.84249445698131E-24"
        iyy="6.65034694932794E-07"
        iyz="-4.68375338513719E-24"
        izz="3.97070446972319E-07" />
    </inertial>
    <visual>
      <origin
        xyz="0 0 0"
        rpy="0 0 0" />
      <geometry>
        <mesh
          filename="package://model20/meshes/right_rear_wheel_suspension.STL" />
      </geometry>
      <material
        name="">
        <color
          rgba="0.898039215686275 0.917647058823529 0.929411764705882 1" />
      </material>
    </visual>
    <collision>
      <origin
        xyz="0 0 0"
        rpy="0 0 0" />
      <geometry>
        <mesh
          filename="package://model20/meshes/right_rear_wheel_suspension.STL" />
      </geometry>
    </collision>
  </link>
  <joint
    name="right_rear_wheel_suspension_joint"
    type="prismatic">
    <origin
      xyz="-0.293 -0.0084978 -0.030998"
      rpy="1.5708 0 -1.5708" />
    <parent
      link="base_link" />
    <child
      link="right_rear_wheel_suspension" />
    <axis
      xyz="0 1 0" />
    <limit
      lower="0"
      upper="0"
      effort="0"
      velocity="0" />
  </joint>
  <link
    name="right_rear_wheel">
    <inertial>
      <origin
        xyz="0 -0.0404395006329033 0"
        rpy="0 0 0" />
      <mass
        value="0.342512288692214" />
      <inertia
        ixx="0.000165711359519628"
        ixy="-5.89883523403532E-22"
        ixz="4.24561514707314E-21"
        iyy="0.00011406556894596"
        iyz="2.89680955317883E-21"
        izz="0.000165711359519628" />
    </inertial>
    <visual>
      <origin
        xyz="0 0 0"
        rpy="0 0 0" />
      <geometry>
        <mesh
          filename="package://model20/meshes/right_rear_wheel.STL" />
      </geometry>
      <material
        name="">
        <color
          rgba="0.898039215686275 0.917647058823529 0.929411764705882 1" />
      </material>
    </visual>
    <collision>
      <origin
        xyz="0 0 0"
        rpy="0 0 0" />
      <geometry>
        <mesh
          filename="package://model20/meshes/right_rear_wheel.STL" />
      </geometry>
    </collision>
  </link>
  <joint
    name="right_rear_wheel_joint"
    type="fixed">
    <origin
      xyz="0 -0.019515762701871 0"
      rpy="0 0 0" />
    <parent
      link="right_rear_wheel_suspension" />
    <child
      link="right_rear_wheel" />
    <axis
      xyz="0 0 0" />
  </joint>
</robot>